Workbook

Sheet Guideline
A1: Guideline to make and understand Unit Test Case
A3: 1. Overview
A4: - In the template, Unit test cases are based on functions. Each sheet presents test cases for one function.
A5: - Cover: General information of the project and Unit Test cases
A6: - FunctionList: The list of Classes and Functions in the document. + To control that the number of Unit TC meets customer's requirement or the norm, user should fill value for 'Normal number of Test cases/KLOC'.
A7: + Click on Function link to open the related Test cases of the function. Note: You should create new Function sheet before creating the link
A8: - Test Report: provive the overview results of Functions Unit test: Test coverage, Test successful coverage (Summary, for normal/abnormal/boundary cases)
A9: Note: Should check the formula of "Sub Total" if you add more functions
A11: 2. Content in Test function sheet
A12: 2.1 Combination of test cases.
A13: - To verify that number of Unit TC meets customer's requirement or not. User has to fill number LOC of tested function and fill value of 'Normal number test cases/KLOC' item in FunctionList sheet, which is required by customer or normal value. The number of lacked TC is shown in 'Lack of test cases' item.
A14: - If the number of Unit TC does not meet the requirement, creator should explain the reasons.
... A47: - Test requirement: Brief description about requirements which are tested in this function, it is not mandatory.

Sheet Cover
B2: UNIT TEST DOCUMENT
A4: Project Name | B4: AlumNect - FPT University Alumni Network & Career Platform | E4: Creator | F4: AnNH
A5: Project Code | B5: ALUMNECT | E5: Issue Date | F5: 46310
A6: Document Code | B6: =B5&"_"&"UnitTest"&"_"&"v1.5" -> ALUMNECT_UnitTest_v1.5 | E6: Version | F6: v1.5
A9: Record of change
A10: Effective Date | B10: Version | C10: Change Item | D10: *A,D,M | E10: Change description | F10: Reference
A11: 46297 | B11: v1.0 | C11: All document | D11: A | E11: Create document and execute 600 unit test cases of 40 modules | F11: Report3_SRS, Report4_SDD, Report5_Test_Report
A12: 46301 | B12: v1.1 | C12: Add modules | D12: A | E12: Add 319 unit test cases of 24 new modules (FE-41 to FE-64): Group Chat, Community Groups, Mentoring, Admin Mentoring & Finance | F12: Report3_SRS, Report4_SDD, Report5_Test_Report
A13: 46301 | B13: v1.2 | C13: Executed By / Date | D13: M | E13: Assign Executed By (HuyLTN, MinhVB, AnNH, TrietNH, HieuPT) evenly for FE-01 to FE-64 and align Executed Date with Report5_Test_Report | F13: Report3_SRS, Report4_SDD, Report5_Test_Report
A14: 46306 | B14: v1.3 | C14: Group Chat & Community Groups | D14: M | E14: HuyLTN reviews unit test cases of FE-41 to FE-48 (validation limits, role checks, status rules) | F14: Report3_SRS, Report4_SDD, Report5_Test_Report
A15: 46310 | B15: v1.4 | C15: Mentoring | D15: M | E15: TrietNH reviews unit test cases of FE-49 to FE-58 (registration, plans, requests, deals, payment, work logs, completion) | F15: Report3_SRS, Report4_SDD, Report5_Test_Report
A16: 46310 | B16: v1.5 | C16: Admin Mentoring & Statistics | D16: M | E16: HieuPT reviews FE-59 to FE-64 (tickets, disputes, ledgers, revenue); MinhVB verifies Functions list and Statistics | F16: Report3_SRS, Report4_SDD, Report5_Test_Report

Sheet Functions
E2: Function List
A4: Project Name | E4: AlumNect - FPT University Alumni Network & Career Platform
A5: Project Code | E5: ALUMNECT
A6: Normal number of Test cases/KLOC | E6: N/A
A7: Test Environment Setup Description | E7: 1. Language / build: Java 21 (compiled and run with JDK 22), Maven 3.9.9, Spring Boot 4.0.6 2. Test framework: JUnit 5 (Jupiter) + Mockito (spring-boot-starter-test), Hibernate Validator for DTO rules 3. Scope: back-end service layer (alumnect-backend); repositories, mailer, WebSocket and external services are mocked, so no database/server is required 4. Command: mvn test -Dtest="FE*" (source: src/test/java/com/alumnect/alumnect_backend/unit)
A10: No | B10: Requirement Name | C10: Class Name | D10: Function Name | E10: Function Code(Optional) | F10: Sheet Name | G10: Description | H10: Pre-Condition
A11: 1 | B11: Register a New Account | C11: AuthServiceImpl | D11: register() | E11: FE-01 | F11: FE-01
A12: 2 | B12: Register a New Account (email OTP activation) | C12: AuthServiceImpl | D12: verifyEmail() | E12: FE-01 | F12: FE-01
A13: 3 | B13: Register a New Account (resend OTP) | C13: AuthServiceImpl | D13: resendOtp() | E13: FE-01 | F13: FE-01
A14: 4 | B14: Sign In (Email & Password) | C14: AuthServiceImpl | D14: login() | E14: FE-02 | F14: FE-02
A15: 5 | B15: Sign In (Refresh session) | C15: AuthServiceImpl | D15: refresh() | E15: FE-02 | F15: FE-02
A16: 6 | B16: Logout | C16: AuthServiceImpl | D16: logout() | E16: FE-02 | F16: FE-02
A17: 7 | B17: Logout (all devices) | C17: AuthServiceImpl | D17: logoutAllDevices() | E17: FE-02 | F17: FE-02
A18: 8 | B18: Sign In with Google (OAuth 2.0) | C18: AuthServiceImpl | D18: loginWithGoogle() | E18: FE-03 | F18: FE-03
A19: 9 | B19: Sign In with Google (register new account) | C19: AuthServiceImpl | D19: registerWithGoogle() | E19: FE-03 | F19: FE-03
A20: 10 | B20: Forgot Password (request OTP) | C20: AuthServiceImpl | D20: forgotPassword() | E20: FE-04 | F20: FE-04
A21: 11 | B21: Forgot Password (verify OTP) | C21: AuthServiceImpl | D21: verifyResetOtp() | E21: FE-04 | F21: FE-04
A22: 12 | B22: Forgot Password (reset password) | C22: AuthServiceImpl | D22: resetPassword() | E22: FE-04 | F22: FE-04
... A228: 218 | B228: Admin Revenue Overview | C228: AdminRevenueServiceImpl | D228: getOverview() | E228: FE-64 | F228: FE-64

Sheet Statistics
A2: UNIT TEST REPORT
A4: Project Name | B4: AlumNect - FPT University Alumni Network & Career Platform | D4: Creator | F4: AnNH
A5: Project Code | B5: ALUMNECT | D5: Reviewer/Approver | F5: All Member
A6: Document Code | B6: =B5&"_"&"UnitTest"&"_"&"v1.1" -> ALUMNECT_UnitTest_v1.1 | D6: Issue Date | F6: 46310
A7: Notes | B7: The function is required to perform correctly based on SRS
A11: No | B11: Function code | C11: Passed | D11: Failed | E11: Untested | F11: N | G11: A | H11: B | I11: Total Test Cases
A12: 1 | B12: FE-01_Register a New Account | C12: ='FE-01'!A7 -> 23 | D12: ='FE-01'!C7 -> 0 | E12: ='FE-01'!F7 -> 0 | F12: ='FE-01'!L7 -> 5 | H12: ='FE-01'!N7 -> 5 | I12: ='FE-01'!O7 -> 23
A13: 2 | B13: FE-02_Sign In & Logout (Email & Password) | C13: ='FE-02'!A7 -> 14 | D13: ='FE-02'!C7 -> 0 | E13: ='FE-02'!F7 -> 0 | F13: ='FE-02'!L7 -> 4 | G13: ='FE-02'!M7 -> 10 | H13: ='FE-02'!N7 -> 0 | I13: ='FE-02'!O7 -> 14
A14: 3 | B14: FE-03_Sign In with Google (OAuth) | C14: ='FE-03'!A7 -> 8 | D14: ='FE-03'!C7 -> 0 | E14: ='FE-03'!F7 -> 0 | F14: ='FE-03'!L7 -> 3 | G14: ='FE-03'!M7 -> 5 | H14: ='FE-03'!N7 -> 0 | I14: ='FE-03'!O7 -> 8
A15: 4 | B15: FE-04_Manage Password (Change / Forgot ) | C15: ='FE-04'!A7 -> 24 | D15: ='FE-04'!C7 -> 0 | E15: ='FE-04'!F7 -> 0 | F15: ='FE-04'!L7 -> 4 | G15: ='FE-04'!M7 -> 14 | H15: ='FE-04'!N7 -> 6 | I15: ='FE-04'!O7 -> 24
A16: 5 | B16: FE-05_View User Profile | C16: ='FE-05'!A7 -> 7 | D16: ='FE-05'!C7 -> 0 | E16: ='FE-05'!F7 -> 0 | F16: ='FE-05'!L7 -> 3 | G16: ='FE-05'!M7 -> 4 | H16: ='FE-05'!N7 -> 0 | I16: ='FE-05'!O7 -> 7
A17: 6 | B17: FE-06_Edit Profile & Manage Skills | C17: ='FE-06'!A7 -> 4 | D17: ='FE-06'!C7 -> 0 | E17: ='FE-06'!F7 -> 0 | F17: ='FE-06'!L7 -> 2 | G17: ='FE-06'!M7 -> 1 | H17: ='FE-06'!N7 -> 1 | I17: ='FE-06'!O7 -> 4
A18: 7 | B18: FE-07_Manage Career Timeline | C18: ='FE-07'!A7 -> 19 | D18: ='FE-07'!C7 -> 0 | E18: ='FE-07'!F7 -> 0 | F18: ='FE-07'!L7 -> 6 | G18: ='FE-07'!M7 -> 8 | H18: ='FE-07'!N7 -> 5 | I18: ='FE-07'!O7 -> 19
A19: 8 | B19: FE-08_Search Users & Alumni Directory | C19: ='FE-08'!A7 -> 11 | D19: ='FE-08'!C7 -> 0 | E19: ='FE-08'!F7 -> 0 | F19: ='FE-08'!L7 -> 9 | G19: ='FE-08'!M7 -> 0 | H19: ='FE-08'!N7 -> 2 | I19: ='FE-08'!O7 -> 11
A20: 9 | B20: FE-09_View Connection Suggestions | C20: ='FE-09'!A7 -> 13 | D20: ='FE-09'!C7 -> 0 | E20: ='FE-09'!F7 -> 0 | F20: ='FE-09'!L7 -> 8 | G20: ='FE-09'!M7 -> 1 | H20: ='FE-09'!N7 -> 4 | I20: ='FE-09'!O7 -> 13
A21: 10 | B21: FE-10_Manage Social Connections (Follow / Followers / Following) | C21: ='FE-10'!A7 -> 17 | D21: ='FE-10'!C7 -> 0 | E21: ='FE-10'!F7 -> 0 | F21: ='FE-10'!L7 -> 5 | G21: ='FE-10'!M7 -> 11 | H21: ='FE-10'!N7 -> 1 | I21: ='FE-10'!O7 -> 17
A22: 11 | B22: FE-11_Admin Console Shell, Access Control & Navigation | C22: ='FE-11'!A7 -> 22 | D22: ='FE-11'!C7 -> 0 | E22: ='FE-11'!F7 -> 0 | F22: ='FE-11'!L7 -> 9 | G22: ='FE-11'!M7 -> 11 | H22: ='FE-11'!N7 -> 2 | I22: ='FE-11'!O7 -> 22
A23: 12 | B23: FE-12_Admin Overview Dashboard & Operations | C23: ='FE-12'!A7 -> 9 | D23: ='FE-12'!C7 -> 0 | E23: ='FE-12'!F7 -> 0 | F23: ='FE-12'!L7 -> 5 | G23: ='FE-12'!M7 -> 0 | H23: ='FE-12'!N7 -> 4 | I23: ='FE-12'!O7 -> 9
A24: 13 | B24: FE-13_User Account Management | C24: ='FE-13'!A7 -> 12 | D24: ='FE-13'!C7 -> 0 | E24: ='FE-13'!F7 -> 0 | F24: ='FE-13'!L7 -> 7 | G24: ='FE-13'!M7 -> 4 | H24: ='FE-13'!N7 -> 1 | I24: ='FE-13'!O7 -> 12
A25: 14 | B25: FE-14_View & Filter Community Posts | C25: ='FE-14'!A7 -> 4 | D25: ='FE-14'!C7 -> 0 | E25: ='FE-14'!F7 -> 0 | F25: ='FE-14'!L7 -> 3 | G25: ='FE-14'!M7 -> 0 | H25: ='FE-14'!N7 -> 1 | I25: ='FE-14'!O7 -> 4
A26: 15 | B26: FE-15_View Community Post Detail | C26: ='FE-15'!A7 -> 3 | D26: ='FE-15'!C7 -> 0 | E26: ='FE-15'!F7 -> 0 | F26: ='FE-15'!L7 -> 2 | G26: ='FE-15'!M7 -> 1 | H26: ='FE-15'!N7 -> 0 | I26: ='FE-15'!O7 -> 3
A27: 16 | B27: FE-16_Hide / Unhide Violating Posts | C27: ='FE-16'!A7 -> 4 | D27: ='FE-16'!C7 -> 0 | E27: ='FE-16'!F7 -> 0 | F27: ='FE-16'!L7 -> 2 | G27: ='FE-16'!M7 -> 2 | H27: ='FE-16'!N7 -> 0 | I27: ='FE-16'!O7 -> 4
A28: 17 | B28: FE-17_Alumni Verification Management Queue | C28: ='FE-17'!A7 -> 12 | D28: ='FE-17'!C7 -> 0 | E28: ='FE-17'!F7 -> 0 | F28: ='FE-17'!L7 -> 5 | G28: ='FE-17'!M7 -> 5 | H28: ='FE-17'!N7 -> 2 | I28: ='FE-17'!O7 -> 12
A29: 18 | B29: FE-18_Violation Reports & Content Moderation Queue | C29: ='FE-18'!A7 -> 7 | D29: ='FE-18'!C7 -> 0 | E29: ='FE-18'!F7 -> 0 | F29: ='FE-18'!L7 -> 4 | G29: ='FE-18'!M7 -> 3 | H29: ='FE-18'!N7 -> 0 | I29: ='FE-18'!O7 -> 7
A30: 19 | B30: FE-19_Broadcast & System Notifications Management | C30: ='FE-19'!A7 -> 29 | D30: ='FE-19'!C7 -> 0 | E30: ='FE-19'!F7 -> 0 | F30: ='FE-19'!L7 -> 13 | G30: ='FE-19'!M7 -> 12 | H30: ='FE-19'!N7 -> 4 | I30: ='FE-19'!O7 -> 29
A31: 20 | B31: FE-20_Create a Post on the Feed | C31: ='FE-20'!A7 -> 17 | D31: ='FE-20'!C7 -> 0 | E31: ='FE-20'!F7 -> 0 | F31: ='FE-20'!L7 -> 6 | G31: ='FE-20'!M7 -> 7 | H31: ='FE-20'!N7 -> 4 | I31: ='FE-20'!O7 -> 17
A32: 21 | B32: FE-21_View Feed & Post Detail | C32: ='FE-21'!A7 -> 13 | D32: ='FE-21'!C7 -> 0 | E32: ='FE-21'!F7 -> 0 | F32: ='FE-21'!L7 -> 6 | G32: ='FE-21'!M7 -> 4 | H32: ='FE-21'!N7 -> 3 | I32: ='FE-21'!O7 -> 13
A33: 22 | B33: FE-22_Edit a Post | C33: ='FE-22'!A7 -> 8 | D33: ='FE-22'!C7 -> 0 | E33: ='FE-22'!F7 -> 0 | F33: ='FE-22'!L7 -> 3 | G33: ='FE-22'!M7 -> 3 | H33: ='FE-22'!N7 -> 2 | I33: ='FE-22'!O7 -> 8
A34: 23 | B34: FE-23_Like & Report a Post | C34: ='FE-23'!A7 -> 17 | D34: ='FE-23'!C7 -> 0 | E34: ='FE-23'!F7 -> 0 | F34: ='FE-23'!L7 -> 5 | G34: ='FE-23'!M7 -> 7 | H34: ='FE-23'!N7 -> 5 | I34: ='FE-23'!O7 -> 17
A35: 24 | B35: FE-24_Comment on a Post | C35: ='FE-24'!A7 -> 18 | D35: ='FE-24'!C7 -> 0 | E35: ='FE-24'!F7 -> 0 | F35: ='FE-24'!L7 -> 5 | G35: ='FE-24'!M7 -> 8 | H35: ='FE-24'!N7 -> 5 | I35: ='FE-24'!O7 -> 18
A36: 25 | B36: FE-25_Bookmark Posts (Save / View Saved) | C36: ='FE-25'!A7 -> 5 | D36: ='FE-25'!C7 -> 0 | E36: ='FE-25'!F7 -> 0 | F36: ='FE-25'!L7 -> 4 | G36: ='FE-25'!M7 -> 1 | H36: ='FE-25'!N7 -> 0 | I36: ='FE-25'!O7 -> 5
A37: 26 | B37: FE-26_Event Attendance & RSVP Management | C37: ='FE-26'!A7 -> 29 | D37: ='FE-26'!C7 -> 0 | E37: ='FE-26'!F7 -> 0 | F37: ='FE-26'!L7 -> 11 | G37: ='FE-26'!M7 -> 11 | H37: ='FE-26'!N7 -> 7 | I37: ='FE-26'!O7 -> 29
A38: 27 | B38: FE-27_Event Lifecycle & Attendance History | C38: ='FE-27'!A7 -> 21 | D38: ='FE-27'!C7 -> 0 | E38: ='FE-27'!F7 -> 0 | F38: ='FE-27'!L7 -> 10 | G38: ='FE-27'!M7 -> 7 | H38: ='FE-27'!N7 -> 4 | I38: ='FE-27'!O7 -> 21
A39: 28 | B39: FE-28_Manage Notifications (View & Manage Notifications) | C39: ='FE-28'!A7 -> 28 | D39: ='FE-28'!C7 -> 0 | E39: ='FE-28'!F7 -> 0 | F39: ='FE-28'!L7 -> 13 | G39: ='FE-28'!M7 -> 5 | H39: ='FE-28'!N7 -> 10 | I39: ='FE-28'!O7 -> 28
A40: 29 | B40: FE-29_View Conversation List (Inbox) | C40: ='FE-29'!A7 -> 21 | D40: ='FE-29'!C7 -> 0 | E40: ='FE-29'!F7 -> 0 | F40: ='FE-29'!L7 -> 14 | G40: ='FE-29'!M7 -> 5 | H40: ='FE-29'!N7 -> 2 | I40: ='FE-29'!O7 -> 21
A41: 30 | B41: FE-30_Send a Direct Message & Chat History | C41: ='FE-30'!A7 -> 18 | D41: ='FE-30'!C7 -> 0 | E41: ='FE-30'!F7 -> 0 | F41: ='FE-30'!L7 -> 8 | G41: ='FE-30'!M7 -> 9 | H41: ='FE-30'!N7 -> 1 | I41: ='FE-30'!O7 -> 18
A42: 31 | B42: FE-31_Alumni Map (View, Filter & Profile Navigation) | C42: ='FE-31'!A7 -> 7 | D42: ='FE-31'!C7 -> 0 | E42: ='FE-31'!F7 -> 0 | F42: ='FE-31'!L7 -> 5 | G42: ='FE-31'!M7 -> 0 | H42: ='FE-31'!N7 -> 2 | I42: ='FE-31'!O7 -> 7
A43: 32 | B43: FE-32_Manage Career Path (View & Explore Alumni Career Journey) | C43: ='FE-32'!A7 -> 15 | D43: ='FE-32'!C7 -> 0 | E43: ='FE-32'!F7 -> 0 | F43: ='FE-32'!L7 -> 8 | G43: ='FE-32'!M7 -> 3 | H43: ='FE-32'!N7 -> 4 | I43: ='FE-32'!O7 -> 15
A44: 33 | B44: FE-33_Manage Posts (Share, Delete & Search Posts) | C44: ='FE-33'!A7 -> 16 | D44: ='FE-33'!C7 -> 0 | E44: ='FE-33'!F7 -> 0 | F44: ='FE-33'!L7 -> 8 | G44: ='FE-33'!M7 -> 5 | H44: ='FE-33'!N7 -> 3 | I44: ='FE-33'!O7 -> 16
A45: 34 | B45: FE-34_Forum Q&A - View, Search & Filter Questions | C45: ='FE-34'!A7 -> 17 | D45: ='FE-34'!C7 -> 0 | E45: ='FE-34'!F7 -> 0 | F45: ='FE-34'!L7 -> 10 | G45: ='FE-34'!M7 -> 3 | H45: ='FE-34'!N7 -> 4 | I45: ='FE-34'!O7 -> 17
...

Sheet FE-01
A2: Function Code | C2: FE-01 | F2: Function Name | L2: FE-01_Register a New Account
A3: Created By | C3: AnNH | F3: Executed By | L3: HuyLTN
A4: Lines of code | C4: 224 | F4: Lack of test cases | L4: =IF(Functions!E6<>"N/A",SUM(C4*Functions!E6/1000,-O7),"N/A") -> N/A
A5: Test requirement | C5: Register account with email OTP activation and OTP resend
A6: Passed | C6: Failed | F6: Untested | L6: N/A/B | O6: Total Test Cases
A7: =COUNTIF(F89:AB89,"P") -> 23 | C7: =COUNTIF(F89:AB89,"F") -> 0 | F7: =SUM(O7,-A7,-C7) -> 0 | L7: =COUNTIF(F88:AB88,"N") -> 5 | M7: =COUNTIF(F88:AB88,"A") -> 13 | N7: =COUNTIF(F88:AB88,"B") -> 5 | O7: =COUNTA(F9:AB9) -> 23
F9: UTCID01 | G9: UTCID02 | H9: UTCID03 | I9: UTCID04 | J9: UTCID05 | K9: UTCID06 | L9: UTCID07 | M9: UTCID08 | N9: UTCID09 | O9: UTCID10 | P9: UTCID11 | Q9: UTCID12 | R9: UTCID13 | S9: UTCID14 | T9: UTCID15 | U9: UTCID16 | V9: UTCID17 | W9: UTCID18 | X9: UTCID19 | Y9: UTCID20 | Z9: UTCID21 | AA9: UTCID22 | AB9: UTCID23
A10: Condition | B10: Precondition
D11: Email is not registered | F11: O | G11: O | J11: O | K11: O | L11: O | M11: O
D12: Student code is not used | F12: O
D13: Role STUDENT and major id 1 exist | F13: O
D14: Role ALUMNI, proofUrl is provided | G14: O
D15: Email already belongs to an ACTIVE account | H15: O
D16: Email belongs to an account in WAITING_APPROVAL status | I16: O
D17: Student code is already used by another profile | J17: O
D18: Role ALUMNI but proofUrl is blank | L18: O
D19: Major id 99 does not exist | M19: O
D20: Account exists with status PENDING (registered but email not verified yet) | N20: O
D21: Validator is applied to RegisterRequest | O21: O | P21: O | Q21: O | R21: O
D22: Account PENDING with role STUDENT | S22: O
D23: Latest EMAIL_VERIFICATION OTP is unused, not expired | S23: O
D24: Account PENDING with role ALUMNI | T24: O
D25: Latest OTP is valid | T25: O
D26: Latest OTP is valid, failedAttempts = 0 | U26: O
D27: Latest OTP has failedAttempts = 4 (one attempt left) | V27: O
D28: Latest OTP already has failedAttempts = 5 (locked) | W28: O
D29: Latest OTP expired 1 minute ago | X29: O
D30: No account exists for the email | Y30: O
D31: Account not yet email-verified | Z31: O | AA31: O
D32: Last OTP was created just now (< 5 minutes ago) | Z32: O
D33: Last OTP was created 6 minutes ago (cool-down of 5 minutes elapsed) | AA33: O
D34: Account email is already verified | AB34: O
B35: Input
D36: RegisterRequest(role=STUDENT, password=Passw0rd1, email with spaces/upper-case) | F36: O
D37: RegisterRequest(role=ALUMNI, proofUrl=https://cdn/proof.png) | G37: O
D38: RegisterRequest(email of the ACTIVE account) | H38: O
D39: RegisterRequest(email of the WAITING_APPROVAL account) | I39: O
D40: RegisterRequest(studentCode=DE180001) | J40: O
D41: RegisterRequest(role=ADMIN) | K41: O
D42: RegisterRequest(role=ALUMNI, proofUrl="") | L42: O
...

Sheet FE-02
A2: Function Code | C2: FE-02 | F2: Function Name | L2: FE-02_Sign In & Logout (Email & Password)
A3: Created By | C3: AnNH | F3: Executed By | L3: MinhVB
A4: Lines of code | C4: 159 | F4: Lack of test cases | L4: =IF(Functions!E6<>"N/A",SUM(C4*Functions!E6/1000,-O7),"N/A") -> N/A
A5: Test requirement | C5: Email/password sign in, token refresh and logout
A6: Passed | C6: Failed | F6: Untested | L6: N/A/B | O6: Total Test Cases
A7: =COUNTIF(F65:T65,"P") -> 14 | C7: =COUNTIF(F65:T65,"F") -> 0 | F7: =SUM(O7,-A7,-C7) -> 0 | L7: =COUNTIF(F64:T64,"N") -> 4 | M7: =COUNTIF(F64:T64,"A") -> 10 | N7: =COUNTIF(F64:T64,"B") -> 0 | O7: =COUNTA(F9:T9) -> 14
F9: UTCID01 | G9: UTCID02 | H9: UTCID03 | I9: UTCID04 | J9: UTCID05 | K9: UTCID06 | L9: UTCID07 | M9: UTCID08 | N9: UTCID09 | O9: UTCID10 | P9: UTCID11 | Q9: UTCID12 | R9: UTCID13 | S9: UTCID14
A10: Condition | B10: Precondition
D11: ACTIVE account with verified email | F11: O
D12: Password matches the stored BCrypt hash | F12: O
D13: No account exists for the email | G13: O
D14: ACTIVE account exists | H14: O
D15: Password does not match the stored hash | H15: O
D16: Account status is LOCKED | I16: O
D17: Password is correct | I17: O
D18: Account status is WAITING_APPROVAL (alumni awaiting admin) | J18: O
D19: Email verified, password correct | J19: O
D20: Account exists but emailVerified = false | K20: O
D21: Password correct | K21: O
D22: Account was created through Google (passwordHash is null) | L22: O
D23: Refresh token JWT is well-formed | M23: O
D24: Stored hash exists, not revoked, not expired | M24: O
D25: Account is ACTIVE | M25: O
D26: Refresh token JWT cannot be parsed (tampered/expired signature) | N26: O
D27: Refresh token was already revoked (replay attack) | O27: O
D28: Stored refresh token expired 1 minute ago | P28: O
D29: Refresh token hash exists in database | Q29: O
D30: Refresh token hash does not exist in database | R30: O
D31: Account exists for the email | S31: O
B32: Input
D33: LoginRequest(email, password), userAgent, ipAddress | F33: O
D34: LoginRequest(unknown email, any password) | G34: O
D35: LoginRequest(email, wrong password) | H35: O
D36: LoginRequest(email, password) | I36: O | J36: O | K36: O | L36: O
D37: RefreshRequest(refreshToken), userAgent, ipAddress | M37: O
D38: RefreshRequest(refreshToken=garbage) | N38: O
D39: RefreshRequest(revoked refresh token) | O39: O
D40: RefreshRequest(expired refresh token) | P40: O
D41: LogoutRequest(refreshToken) | Q41: O
D42: LogoutRequest(unknown refreshToken) | R42: O
...

Sheet FE-03
A2: Function Code | C2: FE-03 | F2: Function Name | L2: FE-03_Sign In with Google (OAuth)
A3: Created By | C3: AnNH | F3: Executed By | L3: AnNH
A4: Lines of code | C4: 268 | F4: Lack of test cases | L4: =IF(Functions!E6<>"N/A",SUM(C4*Functions!E6/1000,-O7),"N/A") -> N/A
A5: Test requirement | C5: Google OAuth sign in and new account registration
A6: Passed | C6: Failed | F6: Untested | L6: N/A/B | O6: Total Test Cases
A7: =COUNTIF(F44:T44,"P") -> 8 | C7: =COUNTIF(F44:T44,"F") -> 0 | F7: =SUM(O7,-A7,-C7) -> 0 | L7: =COUNTIF(F43:T43,"N") -> 3 | M7: =COUNTIF(F43:T43,"A") -> 5 | N7: =COUNTIF(F43:T43,"B") -> 0 | O7: =COUNTA(F9:T9) -> 8
F9: UTCID01 | G9: UTCID02 | H9: UTCID03 | I9: UTCID04 | J9: UTCID05 | K9: UTCID06 | L9: UTCID07 | M9: UTCID08
A10: Condition | B10: Precondition
D11: Google token valid (aud matches, email_verified=true) | F11: O
D12: Google account already linked to an ACTIVE user | F12: O
D13: Google token valid | G13: O | K13: O | L13: O | M13: O
D14: Google account not linked and email is not registered | G14: O
D15: Google token audience (aud) differs from the configured client id | H15: O
D16: Google reports email_verified = false | I16: O
D17: Google tokeninfo call fails (network error / invalid token) | J17: O
D18: Email is not registered | K18: O | L18: O
D19: Role STUDENT, major exists, student code unused | K19: O
D20: Role ALUMNI with proofUrl | L20: O
D21: Email belongs to an ACTIVE account | M21: O
B22: Input
D23: GoogleLoginRequest(token) | F23: O | G23: O | I23: O | J23: O
D24: GoogleLoginRequest(token issued for another app) | H24: O
D25: GoogleRegisterRequest(role=STUDENT) | K25: O | M25: O
D26: GoogleRegisterRequest(role=ALUMNI, proofUrl) | L26: O
A28: Confirm | B28: Return
D29: LoginResponse with access + refresh tokens | F29: O
D30: lastLoginAt updated | F30: O
D31: LoginResponse with tokens; account ACTIVE, AuthProvider=GOOGLE, avatar taken from Google picture | K31: O
D32: OAuth link UserOAuthProvider saved | K32: O
D33: LoginResponse without tokens (null) and accountStatus=WAITING_APPROVAL | L33: O
D34: VerificationRequest saved | L34: O
B35: Exception
D36: GoogleUserNotFoundException: Tài khoản Google chưa được đăng ký trên hệ thống. (carries email, name, providerUserId) | G36: O
D37: BadRequestException: Token xác thực Google không khớp với Client ID của hệ thống | H37: O
D38: BadRequestException: Tài khoản Google này chưa được xác thực email | I38: O
D39: BadRequestException: Không thể xác thực tài khoản Google vào lúc này. Vui lòng thử lại sau. | J39: O
D40: ConflictException: Email này đã được đăng ký và kích hoạt thành công. Vui lòng đăng nhập. | M40: O
B41: Log message
A43: Result | B43: Type(N : Normal, A : Abnormal, B : Boundary) | F43: N | G43: A | H43: A | I43: A | J43: A | K43: N | L43: N | M43: A
B44: Passed/Failed | F44: P | G44: P | H44: P | I44: P | J44: P | K44: P | L44: P | M44: P
...

Sheet FE-04
A2: Function Code | C2: FE-04 | F2: Function Name | L2: FE-04_Manage Password (Change / Forgot )
A3: Created By | C3: AnNH | F3: Executed By | L3: TrietNH
A4: Lines of code | C4: 101 | F4: Lack of test cases | L4: =IF(Functions!E6<>"N/A",SUM(C4*Functions!E6/1000,-O7),"N/A") -> N/A
A5: Test requirement | C5: Change password and recover forgotten password via OTP
A6: Passed | C6: Failed | F6: Untested | L6: N/A/B | O6: Total Test Cases
A7: =COUNTIF(F84:AC84,"P") -> 24 | C7: =COUNTIF(F84:AC84,"F") -> 0 | F7: =SUM(O7,-A7,-C7) -> 0 | L7: =COUNTIF(F83:AC83,"N") -> 4 | M7: =COUNTIF(F83:AC83,"A") -> 14 | N7: =COUNTIF(F83:AC83,"B") -> 6 | O7: =COUNTA(F9:AC9) -> 24
F9: UTCID01 | G9: UTCID02 | H9: UTCID03 | I9: UTCID04 | J9: UTCID05 | K9: UTCID06 | L9: UTCID07 | M9: UTCID08 | N9: UTCID09 | O9: UTCID10 | P9: UTCID11 | Q9: UTCID12 | R9: UTCID13 | S9: UTCID14 | T9: UTCID15 | U9: UTCID16 | V9: UTCID17 | W9: UTCID18 | X9: UTCID19 | Y9: UTCID20 | Z9: UTCID21 | AA9: UTCID22 | AB9: UTCID23 | AC9: UTCID24
A10: Condition | B10: Precondition
D11: ACTIVE account exists for the email | F11: O
D12: No previous PASSWORD_RESET OTP | F12: O
D13: No account exists for the email | G13: O
D14: Account status is LOCKED | H14: O
D15: Account status is PENDING (email not verified yet) | I15: O
D16: ACTIVE account | J16: O | K16: O
D17: Last PASSWORD_RESET OTP created just now (< 5 minutes) | J17: O
D18: Last PASSWORD_RESET OTP created 6 minutes ago (cool-down elapsed) | K18: O
D19: Latest PASSWORD_RESET OTP is unused, not expired, failedAttempts = 0 | L19: O
D20: Latest OTP valid, failedAttempts = 0 | M20: O
D21: Latest OTP expired | N21: O
D22: User never requested a reset (no PASSWORD_RESET OTP found) | O22: O
D23: Latest PASSWORD_RESET OTP valid | P23: O
D24: OTP was already used | Q24: O
D25: OTP valid | R25: O
D26: OTP has failedAttempts = 4 | S26: O
D27: Authenticated user with local password | T27: O
D28: Old password matches stored hash | T28: O | V28: O | W28: O
D29: Authenticated user exists | U29: O
D30: Old password does not match stored hash | U30: O
D31: Account was created through Google (passwordHash = null) | X31: O
D32: No account exists for the authenticated email | Y32: O
D33: Validator applied to ChangePasswordRequest | Z33: O | AA33: O
D34: Validator applied to ResetPasswordRequest | AB34: O | AC34: O
B35: Input
D36: ForgotPasswordRequest(email with spaces/upper-case) | F36: O
D37: ForgotPasswordRequest(unknown email) | G37: O
D38: ForgotPasswordRequest(email) | H38: O | I38: O | J38: O | K38: O
D39: VerifyResetOtpRequest(email, correct OTP) | L39: O
D40: VerifyResetOtpRequest(email, wrong OTP) | M40: O
D41: VerifyResetOtpRequest(email, OTP) | N41: O | O41: O
D42: ResetPasswordRequest(email, correct OTP, newPassword=NewPassw0rd) | P42: O
...

Sheet FE-05
A2: Function Code | C2: FE-05 | F2: Function Name | L2: FE-05_View User Profile
A3: Created By | C3: AnNH | F3: Executed By | L3: HieuPT
A4: Lines of code | C4: 41 | F4: Lack of test cases | L4: =IF(Functions!E6<>"N/A",SUM(C4*Functions!E6/1000,-O7),"N/A") -> N/A
A5: Test requirement | C5: View own profile and public profiles of other members
A6: Passed | C6: Failed | F6: Untested | L6: N/A/B | O6: Total Test Cases
A7: =COUNTIF(F39:T39,"P") -> 7 | C7: =COUNTIF(F39:T39,"F") -> 0 | F7: =SUM(O7,-A7,-C7) -> 0 | L7: =COUNTIF(F38:T38,"N") -> 3 | M7: =COUNTIF(F38:T38,"A") -> 4 | N7: =COUNTIF(F38:T38,"B") -> 0 | O7: =COUNTA(F9:T9) -> 7
F9: UTCID01 | G9: UTCID02 | H9: UTCID03 | I9: UTCID04 | J9: UTCID05 | K9: UTCID06 | L9: UTCID07
A10: Condition | B10: Precondition
D11: Authenticated user with a profile | F11: O
D12: followers = 7, following = 3 | F12: O
D13: No account exists for the email | G13: O
D14: Account exists but has no profile row | H14: O
D15: Target user is ACTIVE | I15: O | J15: O
D16: Viewer is anonymous (no authentication) | I16: O
D17: Logged-in viewer already follows the target | J17: O
D18: Target user exists but account is LOCKED | K18: O
D19: No user with id 999 | L19: O
B20: Input
D21: email of the logged-in user | F21: O
D22: unknown email | G22: O
D23: email | H23: O
D24: userId = 10 | I24: O | J24: O | K24: O
D25: userId = 999 | L25: O
A27: Confirm | B27: Return
D28: UserProfileResponse with followersCount = 7, followingCount = 3, isFollowing = false | F28: O
D29: UserProfileResponse with isFollowing = false and follow counters | I29: O
D30: UserProfileResponse with isFollowing = true | J30: O
B31: Exception
D32: ResourceNotFoundException: Không tìm thấy tài khoản người dùng với email: ... | G32: O
D33: ResourceNotFoundException: Không tìm thấy hồ sơ cá nhân cho tài khoản: ... | H33: O
D34: BadRequestException: Tài khoản người dùng này chưa được kích hoạt hoặc đã bị khóa. | K34: O
D35: ResourceNotFoundException: Không tìm thấy tài khoản người dùng với ID: 999 | L35: O
B36: Log message
A38: Result | B38: Type(N : Normal, A : Abnormal, B : Boundary) | F38: N | G38: A | H38: A | I38: N | J38: N | K38: A | L38: A
B39: Passed/Failed | F39: P | G39: P | H39: P | I39: P | J39: P | K39: P | L39: P
B40: Executed Date | F40: 46213 | G40: 46213 | H40: 46213 | I40: 46213 | J40: 46213 | K40: 46213 | L40: 46213
B41: Defect ID

Sheet FE-06
A2: Function Code | C2: FE-06 | F2: Function Name | L2: FE-06_Edit Profile & Manage Skills
A3: Created By | C3: AnNH | F3: Executed By | L3: HuyLTN
A4: Lines of code | C4: 41 | F4: Lack of test cases | L4: =IF(Functions!E6<>"N/A",SUM(C4*Functions!E6/1000,-O7),"N/A") -> N/A
A5: Test requirement | C5: Edit profile, upload images and manage skills
A6: Passed | C6: Failed | F6: Untested | L6: N/A/B | O6: Total Test Cases
A7: =COUNTIF(F31:T31,"P") -> 4 | C7: =COUNTIF(F31:T31,"F") -> 0 | F7: =SUM(O7,-A7,-C7) -> 0 | L7: =COUNTIF(F30:T30,"N") -> 2 | M7: =COUNTIF(F30:T30,"A") -> 1 | N7: =COUNTIF(F30:T30,"B") -> 1 | O7: =COUNTA(F9:T9) -> 4
F9: UTCID01 | G9: UTCID02 | H9: UTCID03 | I9: UTCID04
A10: Condition | B10: Precondition
D11: Authenticated user with a profile | F11: O | G11: O
D12: Major id 1 exists | F12: O
D13: Major id 99 does not exist | H13: O
D14: Authenticated user with existing skills | I14: O
B15: Input
D16: UpdateProfileRequest(majorId=1, skills=[Java, React]) | F16: O
D17: UpdateProfileRequest(majorId = null, skills = null) | G17: O
D18: UpdateProfileRequest(majorId = 99) | H18: O
D19: UpdateProfileRequest(skills = [] empty list) | I19: O
A21: Confirm | B21: Return
D22: UserProfileResponse; profile saved with the major | F22: O
D23: Old skills deleted, 2 new UserSkill rows saved | F23: O
D24: Major cleared (null) and existing skills untouched | G24: O
D25: All existing skills deleted and nothing inserted (saveAll not called) | I25: O
B26: Exception
D27: ResourceNotFoundException: Không tìm thấy chuyên ngành với ID: 99 | H27: O
B28: Log message
A30: Result | B30: Type(N : Normal, A : Abnormal, B : Boundary) | F30: N | G30: N | H30: A | I30: B
B31: Passed/Failed | F31: P | G31: P | H31: P | I31: P
B32: Executed Date | F32: 46253 | G32: 46253 | H32: 46253 | I32: 46253
B33: Defect ID

Sheet FE-07
A2: Function Code | C2: FE-07 | F2: Function Name | L2: FE-07_Manage Career Timeline
A3: Created By | C3: AnNH | F3: Executed By | L3: MinhVB
A4: Lines of code | C4: 109 | F4: Lack of test cases | L4: =IF(Functions!E6<>"N/A",SUM(C4*Functions!E6/1000,-O7),"N/A") -> N/A
A5: Test requirement | C5: Add, edit, delete and promote career experiences
A6: Passed | C6: Failed | F6: Untested | L6: N/A/B | O6: Total Test Cases
A7: =COUNTIF(F67:X67,"P") -> 19 | C7: =COUNTIF(F67:X67,"F") -> 0 | F7: =SUM(O7,-A7,-C7) -> 0 | L7: =COUNTIF(F66:X66,"N") -> 6 | M7: =COUNTIF(F66:X66,"A") -> 8 | N7: =COUNTIF(F66:X66,"B") -> 5 | O7: =COUNTA(F9:X9) -> 19
F9: UTCID01 | G9: UTCID02 | H9: UTCID03 | I9: UTCID04 | J9: UTCID05 | K9: UTCID06 | L9: UTCID07 | M9: UTCID08 | N9: UTCID09 | O9: UTCID10 | P9: UTCID11 | Q9: UTCID12 | R9: UTCID13 | S9: UTCID14 | T9: UTCID15 | U9: UTCID16 | V9: UTCID17 | W9: UTCID18 | X9: UTCID19
A10: Condition | B10: Precondition
D11: User has 2 experiences | F11: O
D12: User has no primary experience | G12: O
D13: User exists | H13: O | I13: O | J13: O | K13: O | L13: O | M13: O | N13: O | O13: O | P13: O | Q13: O
D14: Experience id 5 belongs to the user | R14: O
D15: Experience id 404 does not belong to the user / does not exist | S15: O
D16: Experience id 5 is the primary one | T16: O
D17: Another current experience exists | T17: O
D18: Experience id 404 does not exist for the user | U18: O
D19: Experience id 5 is current and primary (started 2022-01-01) | V19: O
D20: Experience id 5 already ended (isCurrent = false) | W20: O
D21: Experience id 5 is current, started 2022-01-01 | X21: O
B22: Input
D23: email | F23: O
D24: ExperienceRequest(isCurrent = true, startDate, no endDate) | G24: O
D25: ExperienceRequest(isCurrent = false, startDate 2020-01-01, endDate 2021-01-01) | H25: O
D26: ExperienceRequest(startDate = null) | I26: O
D27: ExperienceRequest(isCurrent = false, endDate = null) | J27: O
D28: ExperienceRequest(endDate 2019-12-31 < startDate 2020-01-01) | K28: O
D29: ExperienceRequest(endDate = startDate = 2020-01-01) | L29: O
D30: ExperienceRequest(isPrimary = true, isCurrent = false) | M30: O
D31: ExperienceRequest(latitude = 10.5, longitude = null) | N31: O
D32: ExperienceRequest(latitude = 90, longitude = 180) - upper bounds | O32: O
D33: ExperienceRequest(latitude = 90.1) - just above the upper bound | P33: O
D34: ExperienceRequest(longitude = -180.1) - just below the lower bound | Q34: O
D35: id = 5, ExperienceRequest(title = Lead Developer, isCurrent = true) | R35: O
D36: id = 404, ExperienceRequest | S36: O
D37: id = 5 | T37: O
D38: id = 404 | U38: O
D39: id = 5, PromotionRequest(newTitle = Tech Lead, newStartDate = 2024-01-01) | V39: O
D40: id = 5, PromotionRequest | W40: O
D41: PromotionRequest(newStartDate = 2022-01-01) - equal to the old start date | X41: O
A43: Confirm | B43: Return
...

Sheet FE-08
A2: Function Code | C2: FE-08 | F2: Function Name | L2: FE-08_Search Users & Alumni Directory
A3: Created By | C3: AnNH | F3: Executed By | L3: AnNH
A4: Lines of code | C4: 117 | F4: Lack of test cases | L4: =IF(Functions!E6<>"N/A",SUM(C4*Functions!E6/1000,-O7),"N/A") -> N/A
A5: Test requirement | C5: Search and filter the alumni directory
A6: Passed | C6: Failed | F6: Untested | L6: N/A/B | O6: Total Test Cases
A7: =COUNTIF(F49:T49,"P") -> 11 | C7: =COUNTIF(F49:T49,"F") -> 0 | F7: =SUM(O7,-A7,-C7) -> 0 | L7: =COUNTIF(F48:T48,"N") -> 9 | M7: =COUNTIF(F48:T48,"A") -> 0 | N7: =COUNTIF(F48:T48,"B") -> 2 | O7: =COUNTA(F9:T9) -> 11
F9: UTCID01 | G9: UTCID02 | H9: UTCID03 | I9: UTCID04 | J9: UTCID05 | K9: UTCID06 | L9: UTCID07 | M9: UTCID08 | N9: UTCID09 | O9: UTCID10 | P9: UTCID11
A10: Condition | B10: Precondition
D11: Anonymous visitor (no authentication) | F11: O
D12: Repository returns 2 users with profile | F12: O
D13: Repository returns users | G13: O | H13: O | I13: O
D14: No user matches the filters | J14: O
D15: Viewer is logged in (id 99) | K15: O
D16: Viewer follows user 1 and has 3 mutual connections with user 1 | K16: O
D17: User 1 has 5 followers, 2 following | K17: O
D18: A matched user has no profile row | L18: O
D19: Repository returns 1 user | M19: O
D20: Two primary experiences exist for the same user (duplicate rows) | N20: O
D21: Database has cohorts [2018, 2019] and cities [Ha Noi, Da Nang] | O21: O
D22: Database has no profile data | P22: O
B23: Input
D24: query="nguyen", role=ALUMNI, majorId=1, cohort=2018, city="Ha Noi", skill=Java, company=FPT, page=0, size=10, sortBy=createdAt, sortDirection=DESC | F24: O
D25: sortBy=fullName, sortDirection=asc (lower-case) | G25: O
D26: sortBy=cohort, sortDirection=DESC | H26: O
D27: sortBy=unknownField, sortDirection=null | I27: O
D28: query="zzz-no-match" | J28: O
D29: default search | K29: O | L29: O | N29: O
D30: page = 0, size = 1 (smallest page) | M30: O
D31: (no input) | O31: O | P31: O
A33: Confirm | B33: Return
D34: PageResponse with 2 UserDirectoryResponse, totalElements=2, followersCount defaults to 0, isFollowing=false | F34: O
D35: Pageable sorted by profile.fullName ASC | G35: O
D36: Pageable sorted by profile.cohort DESC | H36: O
D37: Falls back to createdAt DESC | I37: O
D38: Empty PageResponse (content = [], totalElements = 0); no batch queries executed | J38: O
D39: Item of user 1: isFollowing=true, mutualFollowsCount=3, followersCount=5, followingCount=2 | K39: O
D40: Fallback item built from the User (email, role, isAccountVerified) instead of failing | L40: O
D41: PageResponse with pageNumber = 0, pageSize = 1 | M41: O
D42: No exception; the first primary experience is kept (merge function) | N42: O
D43: UserFilterOptionsResponse(cohorts=[2018,2019], cities=[Ha Noi, Da Nang]) | O43: O
...

Sheet FE-09
A2: Function Code | C2: FE-09 | F2: Function Name | L2: FE-09_View Connection Suggestions
A3: Created By | C3: AnNH | F3: Executed By | L3: TrietNH
A4: Lines of code | C4: 216 | F4: Lack of test cases | L4: =IF(Functions!E6<>"N/A",SUM(C4*Functions!E6/1000,-O7),"N/A") -> N/A
A5: Test requirement | C5: Show connection suggestions and follow members
A6: Passed | C6: Failed | F6: Untested | L6: N/A/B | O6: Total Test Cases
A7: =COUNTIF(F56:T56,"P") -> 13 | C7: =COUNTIF(F56:T56,"F") -> 0 | F7: =SUM(O7,-A7,-C7) -> 0 | L7: =COUNTIF(F55:T55,"N") -> 8 | M7: =COUNTIF(F55:T55,"A") -> 1 | N7: =COUNTIF(F55:T55,"B") -> 4 | O7: =COUNTA(F9:T9) -> 13
F9: UTCID01 | G9: UTCID02 | H9: UTCID03 | I9: UTCID04 | J9: UTCID05 | K9: UTCID06 | L9: UTCID07 | M9: UTCID08 | N9: UTCID09 | O9: UTCID10 | P9: UTCID11 | Q9: UTCID12 | R9: UTCID13
A10: Condition | B10: Precondition
D11: Visitor not logged in (email = null) | F11: O
D12: Guest candidate is verified and has primary experience 'Dev @ FPT' and 4 followers | F12: O
D13: Viewer logged in with major SE | G13: O
D14: Candidate has the same major SE | G14: O
D15: Viewer cohort 2018 | H15: O | I15: O | J15: O
D16: Candidate cohort 2018 | H16: O
D17: Candidate cohort 2019 (difference = 1) | I17: O
D18: Candidate cohort 2021 (difference = 3, outside the 0..2 window) | J18: O
D19: Viewer city Ha Noi | K19: O
D20: Candidate city "ha noi" (case-insensitive match) | K20: O
D21: Viewer owns skills Java, React | L21: O
D22: Candidate owns skills java, react, go | L22: O
D23: Candidate A has 0 mutual connections but a high score | M23: O
D24: Candidate B has 2 mutual connections | M24: O
D25: Viewer follows users 7 and 8 | N25: O
D26: 60 candidates available | O26: O | P26: O
D27: No candidate is available | Q27: O
D28: Email does not belong to any account | R28: O
B29: Input
D30: email = null, limit = 5 | F30: O
D31: email = viewer@fpt.edu.vn, limit = 5 | G31: O
D32: email, limit = 5 | H32: O | I32: O | J32: O | K32: O | L32: O | M32: O | N32: O | Q32: O
D33: limit = 0 (non-positive) | O33: O
D34: limit = 100 (above the maximum) | P34: O
D35: email = ghost@fpt.edu.vn | R35: O
A37: Confirm | B37: Return
D38: 1 suggestion; matchScore = 40 (experience) + 30 (verified) + 4 (followers) = 74 | F38: O
D39: reason badges: "Dev @ FPT", "Cựu sinh viên tiêu biểu" | F39: O
D40: Badge "Cùng ngành SE" and score includes +30 | G40: O
D41: Badge "Cùng khóa K2018" and score +25 | H41: O
D42: Badge "Sát khóa (K2019)" and score +15 | I42: O
D43: No cohort score; fallback badge "Thành viên cộng đồng FPTU", matchScore = 0 | J43: O
...

Sheet FE-10
A2: Function Code | C2: FE-10 | F2: Function Name | L2: FE-10_Manage Social Connections (Follow / Followers / Following)
A3: Created By | C3: AnNH | F3: Executed By | L3: HieuPT
A4: Lines of code | C4: 154 | F4: Lack of test cases | L4: =IF(Functions!E6<>"N/A",SUM(C4*Functions!E6/1000,-O7),"N/A") -> N/A
A5: Test requirement | C5: Follow / unfollow members and view followers / following
A6: Passed | C6: Failed | F6: Untested | L6: N/A/B | O6: Total Test Cases
A7: =COUNTIF(F66:V66,"P") -> 17 | C7: =COUNTIF(F66:V66,"F") -> 0 | F7: =SUM(O7,-A7,-C7) -> 0 | L7: =COUNTIF(F65:V65,"N") -> 5 | M7: =COUNTIF(F65:V65,"A") -> 11 | N7: =COUNTIF(F65:V65,"B") -> 1 | O7: =COUNTA(F9:V9) -> 17
F9: UTCID01 | G9: UTCID02 | H9: UTCID03 | I9: UTCID04 | J9: UTCID05 | K9: UTCID06 | L9: UTCID07 | M9: UTCID08 | N9: UTCID09 | O9: UTCID10 | P9: UTCID11 | Q9: UTCID12 | R9: UTCID13 | S9: UTCID14 | T9: UTCID15 | U9: UTCID16 | V9: UTCID17
A10: Condition | B10: Precondition
D11: Both accounts ACTIVE | F11: O
D12: Not following yet | F12: O
D13: Follower email does not exist | G13: O
D14: Target user id 404 does not exist | H14: O | O14: O
D15: Logged-in user id = 1 | I15: O
D16: Follower account is LOCKED | J16: O
D17: Target account is LOCKED | K17: O
D18: Follow relation already exists | L18: O
D19: Two concurrent requests: unique constraint is violated while saving | M19: O
D20: Follow relation exists | N20: O
D21: Target exists but is not followed by the user | P21: O
D22: Target user 2 is ACTIVE | Q22: O
D23: Follower 3 has primary experience 'Dev @ FPT' and no declared headline | Q23: O
D24: Logged-in viewer follows follower 3 | Q24: O
D25: Target user is LOCKED | R25: O
D26: User id 404 does not exist | S26: O
D27: User 2 follows user 3 who has no profile row and no experience | T27: O
D28: Viewer is anonymous | T28: O
D29: Followed user declared headline "Backend Engineer" | U29: O
D30: Target user 2 has no followers | V30: O
B31: Input
D32: followerEmail = me@fpt.edu.vn, followingId = 2 | F32: O
D33: followerEmail = ghost@fpt.edu.vn, followingId = 2 | G33: O
D34: followerEmail, followingId = 404 | H34: O | O34: O
D35: followingId = 1 (self) | I35: O
D36: followerEmail, followingId = 2 | J36: O | K36: O | L36: O | M36: O | N36: O | P36: O
D37: viewerEmail = me@fpt.edu.vn, userId = 2, Pageable(0, 10) | Q37: O
D38: viewerEmail, userId = 2, Pageable | R38: O
D39: viewerEmail, userId = 404, Pageable | S39: O
D40: viewerEmail = null, userId = 2, Pageable(0, 10) | T40: O | V40: O
D41: viewerEmail = null, userId = 2, Pageable | U41: O
A43: Confirm | B43: Return
...

Sheet FE-11
A2: Function Code | C2: FE-11 | F2: Function Name | L2: FE-11_Admin Console Shell, Access Control & Navigation
A3: Created By | C3: AnNH | F3: Executed By | L3: HuyLTN
A4: Lines of code | C4: 77 | F4: Lack of test cases | L4: =IF(Functions!E6<>"N/A",SUM(C4*Functions!E6/1000,-O7),"N/A") -> N/A
A5: Test requirement | C5: Admin access control, sidebar navigation and logout
A6: Passed | C6: Failed | F6: Untested | L6: N/A/B | O6: Total Test Cases
A7: =COUNTIF(F80:AA80,"P") -> 22 | C7: =COUNTIF(F80:AA80,"F") -> 0 | F7: =SUM(O7,-A7,-C7) -> 0 | L7: =COUNTIF(F79:AA79,"N") -> 9 | M7: =COUNTIF(F79:AA79,"A") -> 11 | N7: =COUNTIF(F79:AA79,"B") -> 2 | O7: =COUNTA(F9:AA9) -> 22
F9: UTCID01 | G9: UTCID02 | H9: UTCID03 | I9: UTCID04 | J9: UTCID05 | K9: UTCID06 | L9: UTCID07 | M9: UTCID08 | N9: UTCID09 | O9: UTCID10 | P9: UTCID11 | Q9: UTCID12 | R9: UTCID13 | S9: UTCID14 | T9: UTCID15 | U9: UTCID16 | V9: UTCID17 | W9: UTCID18 | X9: UTCID19 | Y9: UTCID20 | Z9: UTCID21 | AA9: UTCID22
A10: Condition | B10: Precondition
D11: User ADMIN, id=1, accountVerified = true | F11: O
D12: Access-token lifetime configured to 24 hours (86400000 ms) | G12: O
D13: Refresh-token lifetime configured to 7 days | H13: O
D14: Fresh token issued for admin@fpt.edu.vn | I14: O
D15: Token belongs to admin@fpt.edu.vn | J15: O
D16: Token lifetime is negative, so the token is already expired | K16: O
D17: Token payload/signature altered after signing | L17: O
D18: Token is not a JWT | M18: O
D19: Authorization: Bearer <valid token> of an ADMIN | N19: O
D20: validateToken returns true | N20: O
D21: Request has no Authorization header (guest) | O21: O
D22: Authorization header uses another scheme (Basic abc) | P22: O
D23: Bearer token is garbage; JwtService throws while parsing | Q23: O
D24: Token valid but the user no longer exists | R24: O
D25: Token fails validation (expired or user mismatch): validateToken returns false | S25: O
D26: ACTIVE, email-verified ADMIN account | T26: O
D27: Role name already stored with the ROLE_ prefix | U27: O
D28: Account status LOCKED | V28: O
D29: Email not verified | W29: O
D30: No account for the email | X30: O
D31: Google account with passwordHash = null | Y31: O
D32: Endpoints constants used by SecurityConfiguration | Z32: O | AA32: O
B33: Input
D34: generateToken(user) | F34: O | G34: O
D35: generateRefreshToken(user) | H35: O
D36: validateToken(token, UserDetails admin@fpt.edu.vn) | I36: O
D37: validateToken(token, UserDetails other@fpt.edu.vn) | J37: O
D38: extractUsername(expiredToken) | K38: O
D39: extractUsername(tamperedToken) | L39: O
D40: extractUsername("not-a-jwt") | M40: O
D41: HTTP GET /api/v1/admin/dashboard | N41: O
D42: HTTP GET | O42: O | P42: O
...

Sheet FE-12
A2: Function Code | C2: FE-12 | F2: Function Name | L2: FE-12_Admin Overview Dashboard & Operations
A3: Created By | C3: AnNH | F3: Executed By | L3: MinhVB
A4: Lines of code | C4: 79 | F4: Lack of test cases | L4: =IF(Functions!E6<>"N/A",SUM(C4*Functions!E6/1000,-O7),"N/A") -> N/A
A5: Test requirement | C5: Admin dashboard KPIs, registration chart and action items
A6: Passed | C6: Failed | F6: Untested | L6: N/A/B | O6: Total Test Cases
A7: =COUNTIF(F38:T38,"P") -> 9 | C7: =COUNTIF(F38:T38,"F") -> 0 | F7: =SUM(O7,-A7,-C7) -> 0 | L7: =COUNTIF(F37:T37,"N") -> 5 | M7: =COUNTIF(F37:T37,"A") -> 0 | N7: =COUNTIF(F37:T37,"B") -> 4 | O7: =COUNTA(F9:T9) -> 9
F9: UTCID01 | G9: UTCID02 | H9: UTCID03 | I9: UTCID04 | J9: UTCID05 | K9: UTCID06 | L9: UTCID07 | M9: UTCID08 | N9: UTCID09
A10: Condition | B10: Precondition
D11: DB: 100 users (60 students, 35 alumni, 5 admins), 90 ACTIVE, 4 LOCKED, 7 pending verification requests | F11: O
D12: No registrations in the last 7 days | G12: O
D13: DB returns 3 registrations for today (row date type = java.sql.Date) and 2 for yesterday (row date type = LocalDate) | H13: O
D14: DB returns a row with a date given as String and a row with null date | I14: O
D15: No registration data by month | J15: O
D16: DB returns 8 registrations in month 3 and 5 in month 12 | K16: O
D17: DB returns registrations per year: 2024 -> 40, 2025 -> 60 | L17: O
D18: DB returns no yearly rows (empty system) | M18: O
D19: Total users = 12 | M19: O
D20: Empty database: every counter returns 0 | N20: O
B21: Input
D22: getDashboardSummary() | F22: O | G22: O | H22: O | I22: O | J22: O | K22: O | L22: O | M22: O | N22: O
A24: Confirm | B24: Return
D25: AdminDashboardSummaryDto with totalUsers=100, totalStudents=60, totalAlumni=35, totalAdmins=5, activeUsers=90, lockedUsers=4, pendingVerifications=7 | F25: O
D26: registrationsLast7Days has exactly 7 entries from today-6 to today, each with count 0 | G26: O
D27: Last entry (today) count = 3, previous entry (yesterday) count = 2, other days 0 | H27: O
D28: String date is mapped to its day; null-date row is ignored without error | I28: O
D29: registrationsByMonth has exactly 12 entries labelled "Tháng 1" ... "Tháng 12", all 0 | J29: O
D30: "Tháng 3" = 8, "Tháng 12" = 5, remaining months 0 | K30: O
D31: registrationsByYear = ["Năm 2024":40, "Năm 2025":60] | L31: O
D32: Fallback: one entry "Năm <current year>" with count = totalUsers = 12 | M32: O
D33: All KPI counters are 0; trend lists still have 7 / 12 / 1 entries (no exception) | N33: O
B34: Exception
B35: Log message
A37: Result | B37: Type(N : Normal, A : Abnormal, B : Boundary) | F37: N | G37: B | H37: N | I37: N | J37: B | K37: N | L37: N | M37: B | N37: B
B38: Passed/Failed | F38: P | G38: P | H38: P | I38: P | J38: P | K38: P | L38: P | M38: P | N38: P
B39: Executed Date | F39: 46210 | G39: 46210 | H39: 46210 | I39: 46210 | J39: 46210 | K39: 46210 | L39: 46210 | M39: 46210 | N39: 46210
B40: Defect ID

Sheet FE-13
A2: Function Code | C2: FE-13 | F2: Function Name | L2: FE-13_User Account Management
A3: Created By | C3: AnNH | F3: Executed By | L3: AnNH
A4: Lines of code | C4: 88 | F4: Lack of test cases | L4: =IF(Functions!E6<>"N/A",SUM(C4*Functions!E6/1000,-O7),"N/A") -> N/A
A5: Test requirement | C5: Admin user list, filters, detail and lock / unlock
A6: Passed | C6: Failed | F6: Untested | L6: N/A/B | O6: Total Test Cases
A7: =COUNTIF(F50:T50,"P") -> 12 | C7: =COUNTIF(F50:T50,"F") -> 0 | F7: =SUM(O7,-A7,-C7) -> 0 | L7: =COUNTIF(F49:T49,"N") -> 7 | M7: =COUNTIF(F49:T49,"A") -> 4 | N7: =COUNTIF(F49:T49,"B") -> 1 | O7: =COUNTA(F9:T9) -> 12
F9: UTCID01 | G9: UTCID02 | H9: UTCID03 | I9: UTCID04 | J9: UTCID05 | K9: UTCID06 | L9: UTCID07 | M9: UTCID08 | N9: UTCID09 | O9: UTCID10 | P9: UTCID11 | Q9: UTCID12
A10: Condition | B10: Precondition
D11: 2 users match; user 1 owns a mentor profile (id 55), user 2 does not | F11: O
D12: No user matches the filters | G12: O
D13: One mentor with two mentor-profile rows (duplicates) | H13: O
D14: Exactly 1 user in the system | I14: O
D15: User 1 and profile exist; user owns mentor profile id 55 | J15: O
D16: User 1 and profile exist; no mentor profile | K16: O
D17: No user with id 999 | L17: O | Q17: O
D18: User 1 exists but has no profile row | M18: O
D19: ACTIVE user 1 exists | N19: O
D20: LOCKED user 1 exists | O20: O
D21: User 1 exists | P21: O
B22: Input
D23: query="nguyen", role=STUDENT, status=ACTIVE, majorId=1, cohort=2020, page=0, size=10 | F23: O
D24: query="zzz", page=0, size=10 | G24: O
D25: page=0, size=10 | H25: O
D26: page=0, size=1 | I26: O
D27: id = 1 | J27: O | K27: O | M27: O
D28: id = 999 | L28: O
D29: id = 1, AdminUpdateUserStatusDto(status = LOCKED) | N29: O
D30: id = 1, status = "active" (lower-case) | O30: O
D31: id = 1, status = "BANNED" (not an AccountStatus) | P31: O
D32: id = 999, status = LOCKED | Q32: O
A34: Confirm | B34: Return
D35: PageResponse with 2 AdminUserDto; user 1 hasMentorProfile=true & mentorProfileId=55; user 2 hasMentorProfile=false | F35: O
D36: Empty PageResponse; profile and mentor-profile lookups are skipped | G36: O
D37: No exception (merge function keeps the first); mentorProfileId = first row id | H37: O
D38: PageResponse pageNumber=0, pageSize=1, totalPages=1, last=true | I38: O
D39: AdminUserDto with hasMentorProfile=true, mentorProfileId=55 | J39: O
D40: AdminUserDto with hasMentorProfile=false | K40: O
D41: Void; user.accountStatus = LOCKED and the user is saved | N41: O
D42: Void; user.accountStatus = ACTIVE (status is case-insensitive) | O42: O
B43: Exception
...

Sheet FE-14
A2: Function Code | C2: FE-14 | F2: Function Name | L2: FE-14_View & Filter Community Posts
A3: Created By | C3: AnNH | F3: Executed By | L3: TrietNH
A4: Lines of code | C4: 41 | F4: Lack of test cases | L4: =IF(Functions!E6<>"N/A",SUM(C4*Functions!E6/1000,-O7),"N/A") -> N/A
A5: Test requirement | C5: Admin post list with type, status and search filters
A6: Passed | C6: Failed | F6: Untested | L6: N/A/B | O6: Total Test Cases
A7: =COUNTIF(F29:T29,"P") -> 4 | C7: =COUNTIF(F29:T29,"F") -> 0 | F7: =SUM(O7,-A7,-C7) -> 0 | L7: =COUNTIF(F28:T28,"N") -> 3 | M7: =COUNTIF(F28:T28,"A") -> 0 | N7: =COUNTIF(F28:T28,"B") -> 1 | O7: =COUNTA(F9:T9) -> 4
F9: UTCID01 | G9: UTCID02 | H9: UTCID03 | I9: UTCID04
A10: Condition | B10: Precondition
D11: 2 posts match; post 1 is a recruitment post linked to job 7, post 2 an event post linked to event 9 | F11: O
D12: No post matches the filters | G12: O
D13: Two posts reference the same job id 7 | H13: O
D14: Posts without job / event | I14: O
B15: Input
D16: query="fpt", author="", status="ACTIVE", type="RECRUITMENT", page=0, size=10 | F16: O
D17: query="zzz", page=0, size=10 | G17: O
D18: page=0, size=10 | H18: O | I18: O
A20: Confirm | B20: Return
D21: PageResponse with 2 AdminPostResponse; mapper receives the matching JobPosting / Event for each post | F21: O
D22: Empty PageResponse (content=[], totalElements=0); no job/event lookup | G22: O
D23: Job ids are de-duplicated: JobPostingRepository.findAllById is called once with [7] | H23: O
D24: Mapper is called with job = null, event = null; repositories are not queried | I24: O
B25: Exception
B26: Log message
A28: Result | B28: Type(N : Normal, A : Abnormal, B : Boundary) | F28: N | G28: N | H28: B | I28: N
B29: Passed/Failed | F29: P | G29: P | H29: P | I29: P
B30: Executed Date | F30: 46227 | G30: 46227 | H30: 46227 | I30: 46227
B31: Defect ID

Sheet FE-15
A2: Function Code | C2: FE-15 | F2: Function Name | L2: FE-15_View Community Post Detail
A3: Created By | C3: AnNH | F3: Executed By | L3: HieuPT
A4: Lines of code | C4: 7 | F4: Lack of test cases | L4: =IF(Functions!E6<>"N/A",SUM(C4*Functions!E6/1000,-O7),"N/A") -> N/A
A5: Test requirement | C5: Admin post detail, event card and job listing card
A6: Passed | C6: Failed | F6: Untested | L6: N/A/B | O6: Total Test Cases
A7: =COUNTIF(F26:T26,"P") -> 3 | C7: =COUNTIF(F26:T26,"F") -> 0 | F7: =SUM(O7,-A7,-C7) -> 0 | L7: =COUNTIF(F25:T25,"N") -> 2 | M7: =COUNTIF(F25:T25,"A") -> 1 | N7: =COUNTIF(F25:T25,"B") -> 0 | O7: =COUNTA(F9:T9) -> 3
F9: UTCID01 | G9: UTCID02 | H9: UTCID03
A10: Condition | B10: Precondition
D11: Post 1 exists, linked to job 7 and event 9 | F11: O
D12: Post 1 exists without job/event | G12: O
D13: No post with id 404 | H13: O
B14: Input
D15: id = 1 | F15: O | G15: O
D16: id = 404 | H16: O
A18: Confirm | B18: Return
D19: AdminPostResponse built with the job and the event | F19: O
D20: AdminPostResponse built with job = null and event = null | G20: O
B21: Exception
D22: ResourceNotFoundException: Không tìm thấy bài viết với ID: 404 | H22: O
B23: Log message
A25: Result | B25: Type(N : Normal, A : Abnormal, B : Boundary) | F25: N | G25: N | H25: A
B26: Passed/Failed | F26: P | G26: P | H26: P
B27: Executed Date | F27: 46252 | G27: 46252 | H27: 46252
B28: Defect ID

Sheet FE-16
A2: Function Code | C2: FE-16 | F2: Function Name | L2: FE-16_Hide / Unhide Violating Posts
A3: Created By | C3: AnNH | F3: Executed By | L3: HuyLTN
A4: Lines of code | C4: 12 | F4: Lack of test cases | L4: =IF(Functions!E6<>"N/A",SUM(C4*Functions!E6/1000,-O7),"N/A") -> N/A
A5: Test requirement | C5: Admin hide / unhide violating posts
A6: Passed | C6: Failed | F6: Untested | L6: N/A/B | O6: Total Test Cases
A7: =COUNTIF(F30:T30,"P") -> 4 | C7: =COUNTIF(F30:T30,"F") -> 0 | F7: =SUM(O7,-A7,-C7) -> 0 | L7: =COUNTIF(F29:T29,"N") -> 2 | M7: =COUNTIF(F29:T29,"A") -> 2 | N7: =COUNTIF(F29:T29,"B") -> 0 | O7: =COUNTA(F9:T9) -> 4
F9: UTCID01 | G9: UTCID02 | H9: UTCID03 | I9: UTCID04
A10: Condition | B10: Precondition
D11: Post 1 is ACTIVE | F11: O
D12: Post 1 is HIDDEN | G12: O
D13: Post 1 is DELETED | H13: O
D14: No post with id 404 | I14: O
B15: Input
D16: id = 1, isHidden = true | F16: O | H16: O
D17: id = 1, isHidden = false | G17: O
D18: id = 404, isHidden = true | I18: O
A20: Confirm | B20: Return
D21: Void; post status = HIDDEN and saved | F21: O
D22: Void; post status = ACTIVE and saved; no notification | G22: O
B23: Exception
D24: BadRequestException: Bài viết này đã bị xóa khỏi hệ thống, không thể thực hiện thao tác ẩn hoặc mở ẩn. | H24: O
D25: ResourceNotFoundException: Không tìm thấy bài viết với ID: 404 | I25: O
B26: Log message
D27: Report-resolved notification sent to the post author | F27: O
A29: Result | B29: Type(N : Normal, A : Abnormal, B : Boundary) | F29: N | G29: N | H29: A | I29: A
B30: Passed/Failed | F30: P | G30: P | H30: P | I30: P
B31: Executed Date | F31: 46273 | G31: 46273 | H31: 46273 | I31: 46273
B32: Defect ID

Sheet FE-17
A2: Function Code | C2: FE-17 | F2: Function Name | L2: FE-17_Alumni Verification Management Queue
A3: Created By | C3: AnNH | F3: Executed By | L3: MinhVB
A4: Lines of code | C4: 62 | F4: Lack of test cases | L4: =IF(Functions!E6<>"N/A",SUM(C4*Functions!E6/1000,-O7),"N/A") -> N/A
A5: Test requirement | C5: Alumni verification queue, proof viewer, approve / reject
A6: Passed | C6: Failed | F6: Untested | L6: N/A/B | O6: Total Test Cases
A7: =COUNTIF(F53:T53,"P") -> 12 | C7: =COUNTIF(F53:T53,"F") -> 0 | F7: =SUM(O7,-A7,-C7) -> 0 | L7: =COUNTIF(F52:T52,"N") -> 5 | M7: =COUNTIF(F52:T52,"A") -> 5 | N7: =COUNTIF(F52:T52,"B") -> 2 | O7: =COUNTA(F9:T9) -> 12
F9: UTCID01 | G9: UTCID02 | H9: UTCID03 | I9: UTCID04 | J9: UTCID05 | K9: UTCID06 | L9: UTCID07 | M9: UTCID08 | N9: UTCID09 | O9: UTCID10 | P9: UTCID11 | Q9: UTCID12
A10: Condition | B10: Precondition
D11: 2 PENDING requests exist | F11: O
D12: No request matches | G12: O
D13: Requests exist | H13: O
D14: Request 9 is PENDING for a WAITING_APPROVAL alumni | I14: O
D15: Request 9 is PENDING | J15: O | K15: O | N15: O
D16: No verification request with id 404 | L16: O
D17: Request 9 is already APPROVED | M17: O
D18: Validator applied to AdminReviewVerificationDto | O18: O | P18: O | Q18: O
B19: Input
D20: status = "PENDING", page = 0, size = 10 | F20: O
D21: status = "APPROVED", page = 0, size = 10 | G21: O
D22: status = "UNKNOWN" (invalid filter) | H22: O
D23: id = 9, AdminReviewVerificationDto(status = APPROVED, reviewNote = "Proof is valid"), adminUser | I23: O
D24: id = 9, AdminReviewVerificationDto(status = REJECTED, reviewNote = "Blurry proof") | J24: O
D25: AdminReviewVerificationDto(status = "approved" lower-case, reviewNote = null) | K25: O
D26: id = 404, AdminReviewVerificationDto(APPROVED) | L26: O
D27: id = 9, AdminReviewVerificationDto(REJECTED) | M27: O
D28: AdminReviewVerificationDto(status = "MAYBE") | N28: O
D29: reviewNote length = 500 (maximum) | O29: O
D30: reviewNote length = 501 (above maximum) | P30: O
D31: status = "PENDING" (only APPROVED|REJECTED allowed) | Q31: O
A33: Confirm | B33: Return
D34: PageResponse with 2 AdminVerificationRequestDto, profiles loaded in a single batch query | F34: O
D35: Empty PageResponse; profile query skipped | G35: O
D36: Invalid status filter is ignored (no exception); full list is returned | H36: O
D37: Void; request APPROVED with reviewer, note and reviewedAt | I37: O
D38: User becomes ACTIVE and accountVerified = true | I38: O
D39: Void; request REJECTED with note | J39: O
D40: User accountVerified = false and account is LOCKED | J40: O
D41: Decision is case-insensitive: request APPROVED, reviewNote stays null | K41: O
D42: No constraint violation | O42: O
B43: Exception
...

Sheet FE-18
A2: Function Code | C2: FE-18 | F2: Function Name | L2: FE-18_Violation Reports & Content Moderation Queue
A3: Created By | C3: AnNH | F3: Executed By | L3: AnNH
A4: Lines of code | C4: 42 | F4: Lack of test cases | L4: =IF(Functions!E6<>"N/A",SUM(C4*Functions!E6/1000,-O7),"N/A") -> N/A
A5: Test requirement | C5: Violation report queue, filters, resolve / dismiss
A6: Passed | C6: Failed | F6: Untested | L6: N/A/B | O6: Total Test Cases
A7: =COUNTIF(F37:T37,"P") -> 7 | C7: =COUNTIF(F37:T37,"F") -> 0 | F7: =SUM(O7,-A7,-C7) -> 0 | L7: =COUNTIF(F36:T36,"N") -> 4 | M7: =COUNTIF(F36:T36,"A") -> 3 | N7: =COUNTIF(F36:T36,"B") -> 0 | O7: =COUNTA(F9:T9) -> 7
F9: UTCID01 | G9: UTCID02 | H9: UTCID03 | I9: UTCID04 | J9: UTCID05 | K9: UTCID06 | L9: UTCID07
A10: Condition | B10: Precondition
D11: 2 reports match the filters | F11: O
D12: No report matches | G12: O
D13: Report 3 is PENDING | H13: O | I13: O
D14: Report 3 exists | J14: O | K14: O
D15: No report with id 404 | L15: O
B16: Input
D17: query="spam", author="", reason="SPAM", status="PENDING", type="GENERAL", postId=10, page=0, size=10 | F17: O
D18: all filters null, page=0, size=10 | G18: O
D19: id = 3, status = "RESOLVED" | H19: O
D20: id = 3, status = " dismissed " (lower-case with spaces) | I20: O
D21: id = 3, status = "PENDING" | J21: O
D22: id = 3, status = "FOO" | K22: O
D23: id = 404, status = "RESOLVED" | L23: O
A25: Confirm | B25: Return
D26: PageResponse with 2 AdminReportResponse and totalElements = 2 | F26: O
D27: Empty PageResponse (content=[], totalElements=0); mapper never called | G27: O
D28: Void; report.status = RESOLVED and saved | H28: O
D29: Void; status is trimmed and case-insensitive: report.status = DISMISSED | I29: O
B30: Exception
D31: BadRequestException: Không thể cập nhật báo cáo quay lại trạng thái PENDING. | J31: O
D32: BadRequestException: Trạng thái báo cáo không hợp lệ: FOO | K32: O
D33: ResourceNotFoundException: Không tìm thấy báo cáo vi phạm với ID: 404 | L33: O
B34: Log message
A36: Result | B36: Type(N : Normal, A : Abnormal, B : Boundary) | F36: N | G36: N | H36: N | I36: N | J36: A | K36: A | L36: A
B37: Passed/Failed | F37: P | G37: P | H37: P | I37: P | J37: P | K37: P | L37: P
B38: Executed Date | F38: 46265 | G38: 46265 | H38: 46265 | I38: 46265 | J38: 46265 | K38: 46265 | L38: 46265
B39: Defect ID

Sheet FE-19
A2: Function Code | C2: FE-19 | F2: Function Name | L2: FE-19_Broadcast & System Notifications Management
A3: Created By | C3: AnNH | F3: Executed By | L3: TrietNH
A4: Lines of code | C4: 163 | F4: Lack of test cases | L4: =IF(Functions!E6<>"N/A",SUM(C4*Functions!E6/1000,-O7),"N/A") -> N/A
A5: Test requirement | C5: System notification history, create, schedule, cancel, archive
A6: Passed | C6: Failed | F6: Untested | L6: N/A/B | O6: Total Test Cases
A7: =COUNTIF(F95:AH95,"P") -> 29 | C7: =COUNTIF(F95:AH95,"F") -> 0 | F7: =SUM(O7,-A7,-C7) -> 0 | L7: =COUNTIF(F94:AH94,"N") -> 13 | M7: =COUNTIF(F94:AH94,"A") -> 12 | N7: =COUNTIF(F94:AH94,"B") -> 4 | O7: =COUNTA(F9:AH9) -> 29
F9: UTCID01 | G9: UTCID02 | H9: UTCID03 | I9: UTCID04 | J9: UTCID05 | K9: UTCID06 | L9: UTCID07 | M9: UTCID08 | N9: UTCID09 | O9: UTCID10 | P9: UTCID11 | Q9: UTCID12 | R9: UTCID13 | S9: UTCID14 | T9: UTCID15 | U9: UTCID16 | V9: UTCID17 | W9: UTCID18 | X9: UTCID19 | Y9: UTCID20 | Z9: UTCID21 | AA9: UTCID22 | AB9: UTCID23 | AC9: UTCID24 | AD9: UTCID25 | AE9: UTCID26 | AF9: UTCID27 | AG9: UTCID28 | AH9: UTCID29
A10: Condition | B10: Precondition
D11: Admin exists | F11: O | G11: O | H11: O | I11: O | J11: O | K11: O | M11: O | N11: O | O11: O | P11: O | Q11: O | R11: O | S11: O | T11: O | U11: O
D12: 2 ACTIVE users in the system | F12: O
D13: Alumni users exist | G13: O
D14: User 11 exists | H14: O
D15: No admin account for the email | L15: O
D16: User 404 does not exist | N16: O
D17: No ACTIVE user for the target role | T17: O
D18: WebSocket push throws for every recipient | U18: O
D19: Notification 7 is SCHEDULED | V19: O | Z19: O
D20: Notification 7 already SENT | W20: O
